<?xml version="1.0"?>
<sdf version="1.9">
  <model name="demo_robot">
    <pose>0 0 0.15 0 0 0</pose>

    <!-- ===================== CHASSIS ===================== -->
    <link name="base_link">
      <inertial>
        <mass>5.0</mass>
        <inertia>
          <ixx>0.0508</ixx>
          <ixy>0</ixy>
          <ixz>0</ixz>
          <iyy>0.0958</iyy>
          <iyz>0</iyz>
          <izz>0.1383</izz>
        </inertia>
      </inertial>
      <visual name="chassis_visual">
        <geometry>
          <box><size>0.4 0.3 0.15</size></box>
        </geometry>
        <material>
          <ambient>0.2 0.4 0.8 1</ambient>
          <diffuse>0.2 0.4 0.8 1</diffuse>
        </material>
      </visual>
      <collision name="chassis_collision">
        <geometry>
          <box><size>0.4 0.3 0.15</size></box>
        </geometry>
      </collision>
    </link>

    <!-- ===================== LEFT WHEEL ===================== -->
    <link name="left_wheel">
      <pose>0 0.175 -0.05 1.5708 0 0</pose>
      <inertial>
        <mass>0.5</mass>
        <inertia>
          <ixx>0.000703</ixx>
          <ixy>0</ixy>
          <ixz>0</ixz>
          <iyy>0.000703</iyy>
          <iyz>0</iyz>
          <izz>0.001406</izz>
        </inertia>
      </inertial>
      <visual name="left_wheel_visual">
        <geometry>
          <cylinder><radius>0.075</radius><length>0.05</length></cylinder>
        </geometry>
        <material>
          <ambient>0.1 0.1 0.1 1</ambient>
          <diffuse>0.1 0.1 0.1 1</diffuse>
        </material>
      </visual>
      <collision name="left_wheel_collision">
        <geometry>
          <cylinder><radius>0.075</radius><length>0.05</length></cylinder>
        </geometry>
        <surface>
          <friction>
            <ode><mu>1.0</mu><mu2>1.0</mu2></ode>
          </friction>
        </surface>
      </collision>
    </link>

    <joint name="left_wheel_joint" type="revolute">
      <parent>base_link</parent>
      <child>left_wheel</child>
      <axis>
        <xyz>0 0 1</xyz>
        <limit><effort>10</effort><velocity>10</velocity></limit>
      </axis>
    </joint>

    <!-- ===================== RIGHT WHEEL ===================== -->
    <link name="right_wheel">
      <pose>0 -0.175 -0.05 1.5708 0 0</pose>
      <inertial>
        <mass>0.5</mass>
        <inertia>
          <ixx>0.000703</ixx>
          <ixy>0</ixy>
          <ixz>0</ixz>
          <iyy>0.000703</iyy>
          <iyz>0</iyz>
          <izz>0.001406</izz>
        </inertia>
      </inertial>
      <visual name="right_wheel_visual">
        <geometry>
          <cylinder><radius>0.075</radius><length>0.05</length></cylinder>
        </geometry>
        <material>
          <ambient>0.1 0.1 0.1 1</ambient>
          <diffuse>0.1 0.1 0.1 1</diffuse>
        </material>
      </visual>
      <collision name="right_wheel_collision">
        <geometry>
          <cylinder><radius>0.075</radius><length>0.05</length></cylinder>
        </geometry>
        <surface>
          <friction>
            <ode><mu>1.0</mu><mu2>1.0</mu2></ode>
          </friction>
        </surface>
      </collision>
    </link>

    <joint name="right_wheel_joint" type="revolute">
      <parent>base_link</parent>
      <child>right_wheel</child>
      <axis>
        <xyz>0 0 1</xyz>
        <limit><effort>10</effort><velocity>10</velocity></limit>
      </axis>
    </joint>

    <!-- ===================== CASTER ===================== -->
    <link name="caster">
      <pose>-0.18 0 -0.09 0 0 0</pose>
      <inertial>
        <mass>0.1</mass>
        <inertia>
          <ixx>0.000036</ixx>
          <ixy>0</ixy>
          <ixz>0</ixz>
          <iyy>0.000036</iyy>
          <iyz>0</iyz>
          <izz>0.000036</izz>
        </inertia>
      </inertial>
      <visual name="caster_visual">
        <geometry>
          <sphere><radius>0.03</radius></sphere>
        </geometry>
        <material>
          <ambient>0.5 0.5 0.5 1</ambient>
          <diffuse>0.5 0.5 0.5 1</diffuse>
        </material>
      </visual>
      <collision name="caster_collision">
        <geometry>
          <sphere><radius>0.03</radius></sphere>
        </geometry>
        <surface>
          <friction>
            <!-- frictionless caster -->
            <ode><mu>0</mu><mu2>0</mu2></ode>
          </friction>
        </surface>
      </collision>
    </link>

    <joint name="caster_joint" type="fixed">
      <parent>base_link</parent>
      <child>caster</child>
    </joint>

    <!-- ===================== LIDAR LINK ===================== -->
    <link name="lidar_link">
      <pose>0 0 0.095 0 0 0</pose>
      <inertial>
        <mass>0.1</mass>
        <inertia>
          <ixx>0.0000045</ixx>
          <ixy>0</ixy>
          <ixz>0</ixz>
          <iyy>0.0000045</iyy>
          <iyz>0</iyz>
          <izz>0.0000045</izz>
        </inertia>
      </inertial>
      <visual name="lidar_visual">
        <geometry>
          <cylinder><radius>0.03</radius><length>0.04</length></cylinder>
        </geometry>
        <material>
          <ambient>0.8 0.2 0.2 1</ambient>
          <diffuse>0.8 0.2 0.2 1</diffuse>
        </material>
      </visual>
      <collision name="lidar_collision">
        <geometry>
          <cylinder><radius>0.03</radius><length>0.04</length></cylinder>
        </geometry>
      </collision>

      <sensor name="lidar" type="gpu_lidar">
        <gz_frame_id>lidar_link</gz_frame_id>
        <pose>0 0 0.02 0 0 0</pose>
        <ray>
          <scan>
            <horizontal>
              <samples>720</samples>
              <resolution>1</resolution>
              <min_angle>-2.356195</min_angle>
              <max_angle>2.356195</max_angle>
            </horizontal>
          </scan>
          <range>
            <min>0.1</min>
            <max>12.0</max>
            <resolution>0.01</resolution>
          </range>
          <noise>
            <type>gaussian</type>
            <mean>0.0</mean>
            <stddev>0.005</stddev>
          </noise>
        </ray>
        <always_on>1</always_on>
        <update_rate>10</update_rate>
        <visualize>true</visualize>
      </sensor>
    </link>

    <joint name="lidar_joint" type="fixed">
      <parent>base_link</parent>
      <child>lidar_link</child>
    </joint>

    <!-- ===================== PLUGINS ===================== -->

    <plugin filename="gz-sim-diff-drive-system"
            name="gz::sim::systems::DiffDrive">
      <left_joint>left_wheel_joint</left_joint>
      <right_joint>right_wheel_joint</right_joint>
      <wheel_separation>0.35</wheel_separation>
      <wheel_radius>0.075</wheel_radius>
      <topic>cmd_vel</topic>
      <odom_topic>odom</odom_topic>
      <tf_topic>tf</tf_topic>
      <frame_id>odom</frame_id>
      <child_frame_id>base_link</child_frame_id>
      <min_velocity>-2</min_velocity>
      <max_velocity>2</max_velocity>
      <min_acceleration>-1</min_acceleration>
      <max_acceleration>1</max_acceleration>
    </plugin>

    <plugin filename="gz-sim-odometry-publisher-system"
            name="gz::sim::systems::OdometryPublisher">
      <odom_frame>odom</odom_frame>
      <robot_base_frame>base_link</robot_base_frame>
    </plugin>

  </model>
</sdf>
