<?xml version="1.0"?>
<sdf version="1.9">
  <world name="preview">
    <physics name="1ms" type="ode">
      <max_step_size>0.001</max_step_size>
      <real_time_factor>1.0</real_time_factor>
    </physics>

    <plugin filename="gz-sim-physics-system"
            name="gz::sim::systems::Physics"/>
    <plugin filename="gz-sim-user-commands-system"
            name="gz::sim::systems::UserCommands"/>
    <plugin filename="gz-sim-scene-broadcaster-system"
            name="gz::sim::systems::SceneBroadcaster"/>

    <light name="sun" type="directional">
      <cast_shadows>true</cast_shadows>
      <pose>0 0 10 0 0 0</pose>
      <diffuse>1 1 1 1</diffuse>
      <specular>0.5 0.5 0.5 1</specular>
      <direction>-0.5 0.1 -0.9</direction>
    </light>

    <model name="ground_plane">
      <static>true</static>
      <link name="link">
        <collision name="collision">
          <geometry><plane><normal>0 0 1</normal></plane></geometry>
        </collision>
        <visual name="visual">
          <geometry><plane><normal>0 0 1</normal><size>20 20</size></plane></geometry>
          <material>
            <ambient>0.8 0.8 0.8 1</ambient>
            <diffuse>0.8 0.8 0.8 1</diffuse>
          </material>
        </visual>
      </link>
    </model>

    <!-- demo_robot inlined to avoid GZ_SIM_RESOURCE_PATH lookup -->
    <model name="demo_robot">
      <pose>0 0 0.15 0 0 0</pose>

      <link name="base_link">
        <inertial>
          <mass>5.0</mass>
          <inertia>
            <ixx>0.0508</ixx><ixy>0</ixy><ixz>0</ixz>
            <iyy>0.0958</iyy><iyz>0</iyz><izz>0.1383</izz>
          </inertia>
        </inertial>
        <visual name="chassis_visual">
          <geometry><box><size>0.4 0.3 0.15</size></box></geometry>
          <material>
            <ambient>0.2 0.4 0.8 1</ambient>
            <diffuse>0.2 0.4 0.8 1</diffuse>
          </material>
        </visual>
        <collision name="chassis_collision">
          <geometry><box><size>0.4 0.3 0.15</size></box></geometry>
        </collision>
      </link>

      <link name="left_wheel">
        <pose>0 0.175 -0.05 1.5708 0 0</pose>
        <inertial>
          <mass>0.5</mass>
          <inertia>
            <ixx>0.000703</ixx><ixy>0</ixy><ixz>0</ixz>
            <iyy>0.000703</iyy><iyz>0</iyz><izz>0.001406</izz>
          </inertia>
        </inertial>
        <visual name="left_wheel_visual">
          <geometry><cylinder><radius>0.075</radius><length>0.05</length></cylinder></geometry>
          <material><ambient>0.1 0.1 0.1 1</ambient><diffuse>0.1 0.1 0.1 1</diffuse></material>
        </visual>
        <collision name="left_wheel_collision">
          <geometry><cylinder><radius>0.075</radius><length>0.05</length></cylinder></geometry>
          <surface><friction><ode><mu>1.0</mu><mu2>1.0</mu2></ode></friction></surface>
        </collision>
      </link>

      <joint name="left_wheel_joint" type="revolute">
        <parent>base_link</parent><child>left_wheel</child>
        <axis><xyz>0 0 1</xyz><limit><effort>10</effort><velocity>10</velocity></limit></axis>
      </joint>

      <link name="right_wheel">
        <pose>0 -0.175 -0.05 1.5708 0 0</pose>
        <inertial>
          <mass>0.5</mass>
          <inertia>
            <ixx>0.000703</ixx><ixy>0</ixy><ixz>0</ixz>
            <iyy>0.000703</iyy><iyz>0</iyz><izz>0.001406</izz>
          </inertia>
        </inertial>
        <visual name="right_wheel_visual">
          <geometry><cylinder><radius>0.075</radius><length>0.05</length></cylinder></geometry>
          <material><ambient>0.1 0.1 0.1 1</ambient><diffuse>0.1 0.1 0.1 1</diffuse></material>
        </visual>
        <collision name="right_wheel_collision">
          <geometry><cylinder><radius>0.075</radius><length>0.05</length></cylinder></geometry>
          <surface><friction><ode><mu>1.0</mu><mu2>1.0</mu2></ode></friction></surface>
        </collision>
      </link>

      <joint name="right_wheel_joint" type="revolute">
        <parent>base_link</parent><child>right_wheel</child>
        <axis><xyz>0 0 1</xyz><limit><effort>10</effort><velocity>10</velocity></limit></axis>
      </joint>

      <link name="caster">
        <pose>-0.18 0 -0.09 0 0 0</pose>
        <inertial>
          <mass>0.1</mass>
          <inertia>
            <ixx>0.000036</ixx><ixy>0</ixy><ixz>0</ixz>
            <iyy>0.000036</iyy><iyz>0</iyz><izz>0.000036</izz>
          </inertia>
        </inertial>
        <visual name="caster_visual">
          <geometry><sphere><radius>0.03</radius></sphere></geometry>
          <material><ambient>0.5 0.5 0.5 1</ambient><diffuse>0.5 0.5 0.5 1</diffuse></material>
        </visual>
        <collision name="caster_collision">
          <geometry><sphere><radius>0.03</radius></sphere></geometry>
          <surface><friction><ode><mu>0</mu><mu2>0</mu2></ode></friction></surface>
        </collision>
      </link>

      <joint name="caster_joint" type="fixed">
        <parent>base_link</parent><child>caster</child>
      </joint>

      <link name="lidar_link">
        <pose>0 0 0.095 0 0 0</pose>
        <inertial>
          <mass>0.1</mass>
          <inertia>
            <ixx>0.0000045</ixx><ixy>0</ixy><ixz>0</ixz>
            <iyy>0.0000045</iyy><iyz>0</iyz><izz>0.0000045</izz>
          </inertia>
        </inertial>
        <visual name="lidar_visual">
          <geometry><cylinder><radius>0.03</radius><length>0.04</length></cylinder></geometry>
          <material><ambient>0.8 0.2 0.2 1</ambient><diffuse>0.8 0.2 0.2 1</diffuse></material>
        </visual>
        <collision name="lidar_collision">
          <geometry><cylinder><radius>0.03</radius><length>0.04</length></cylinder></geometry>
        </collision>
      </link>

      <joint name="lidar_joint" type="fixed">
        <parent>base_link</parent><child>lidar_link</child>
      </joint>

      <plugin filename="gz-sim-diff-drive-system"
              name="gz::sim::systems::DiffDrive">
        <left_joint>left_wheel_joint</left_joint>
        <right_joint>right_wheel_joint</right_joint>
        <wheel_separation>0.35</wheel_separation>
        <wheel_radius>0.075</wheel_radius>
        <topic>cmd_vel</topic>
        <odom_topic>odom</odom_topic>
        <tf_topic>tf</tf_topic>
        <frame_id>odom</frame_id>
        <child_frame_id>base_link</child_frame_id>
      </plugin>

      <plugin filename="gz-sim-odometry-publisher-system"
              name="gz::sim::systems::OdometryPublisher">
        <odom_frame>odom</odom_frame>
        <robot_base_frame>base_link</robot_base_frame>
      </plugin>

    </model>
  </world>
</sdf>
